Workbook
Name County: #REF!
Name Feeding: #REF!

Sheet Interface
A1: Storm Surge Shelter Demand Model – Input Configuration
A2: Welcome! This interface is designed to help the user configure inputs for the Storm Surge Shelter Demand Model. Instructions: - Step 1: Required inputs from NHC forecasts. - Steps 2, 3, 4, 5: Inputs are filled with default values. Modification of these inputs is optional and at the user's discretion (refer to Data Dictionary tab). - Step 5: A Python code snippet will be automatically generated. Copy directly into Google Colab. - Step 6: Paste code snippet directly from Google Colab.
A3: Select the variable names to see their definition and any associated data validation rules
A4: Step 1: Inputs from NHC forecast (required)
A6: Storm ID | C6: AL142018
A7: Storm Name | C7: Michael
A8: Latest Advisory # | C8: 22
A9: Storm Year | C9: 2018
A11: Step 2: Residential building types to include (optional)
A12: Building Type | C12: Include (Y/N)
A13: Single Family Dwelling | C13: Y
A14: Manufactured/Mobile Home | C14: Y
A15: Multi-Family Dwelling: Duplex | C15: Y
A16: Multi-Family Dwelling: 3-4 units | C16: Y
A17: Multi-Family Dwelling: 5-9 units | C17: Y
A18: Multi-Family Dwelling: 10-19 units | C18: Y
A19: Multi-Family Dwelling: 20-49 units | C19: Y
A20: Multi-Family Dwelling: 50+ units | C20: Y
A21: Temporary Lodging (Hotel/Motel) | C21: N
A22: Institutional Dormitory (group housing - military, college) | C22: N
A23: Nursing Home | C23: N
A25: Step 3: Criteria for damage assessment categories (optional)
A26: Predicted Storm Surge Height | C26: Category Label
A27: >9 feet | C27: destroyed
A28: >6 feet | C28: destroyed
A29: >3 feet | C29: major
A30: >1 foot | C30: minor
A32: Step 4: Geographic Level of Results (optional)
A33: Geography | C33: census tract
A35: Step 5: Run Colab Notebook
B36: =_xludf.UNICHAR(10227) -> #NAME? | D36: =_xludf.UNICHAR(10227) -> #NAME?

Sheet Data Dictionary
A1: Step | B1: Variable Name | C1: Data Validation Rules | D1: Definition
A2: 1 | B2: Storm ID | D2: The NHC storm ID associated with this event.
A3: 1 | B3: Storm Name | D3: The NHC storm name associated with this event.
A4: 1 | B4: Latest Advisory # | C4: 1 - may contain a letter (e.g. a, b, c) | D4: The latest NHC advisory associated with this event.
A5: 1 | B5: Storm Year | D5: The calendar year associated with the event (defaults to current year).
B6: Criteria for damage levels
B7: % Destroyed
B8: % Major Damage
B9: High
B10: Medium
B11: Low
B12: SVI Mapping Threshold | C12: Each cell must have a value greater than equal to 0 and smaller or equal to 1. | D12: The mapping of SVI value ranges to % Non-Habitable Residents Seeking Shelter.
B13: SVI | C13: N/A | D13: Social Vulnerability Index - The CDC’s SVI is an index that ranks a tract's social vulnerability. SVI is a percentile ranking. Score ranges from 0 (lowest vulnerability) to 1 (highest vulnerability).

Sheet archive data dictionary
A1: Step | B1: Variable Name | C1: Data Validation Rules | D1: Definition
A2: 1 | B2: Storm ID | C2: N/A | D2: The NHC storm ID associated with this event.
A3: 1 | B3: Storm Name | C3: N/A | D3: The NHC storm name associated with this event.
A4: 1 | B4: Latest Advisory # | C4: 1 - | D4: The latest NHC advisory associated with this event.
A5: 1 | B5: Storm Year | D5: The calendar year associated with the event (defaults to current year).
B6: Criteria for damage levels
B7: % Destroyed
B8: % Major Damage
B9: High
B10: Medium
B11: Low
A12: 2 | B12: Intensity Metric | C12: Select from dropdown menu. | D12: The PGA used to assess earthquake intensity (whether to use the low PGA, medium PGA, or the high PGA detected).
A13: 3 | B13: Building Usability Thresholds | C13: Each cell must have a value greater than equal to 0 and smaller or equal to 1; Each row sums up to 1. | D13: Usability Ratios for each damage level and usability class.
A14: 3 | B14: Slight Damage | C14: N/A | D14: Small cracks at corners of door and window openings and wall-ceiling intersections; small cracks on stucco and plaster walls. Some slippage may be observed at bolted connections.
A15: 3 | B15: Moderate Damage | C15: N/A | D15: Larger cracks at corners of door and window openings; small diagonal cracks across shear wall panels exhibited by cracks in stucco and gypsum wall panels; minor slack (less than 1/8” extension) in diagonal rod bracing requiring re-tightening; minor lateral set at store fronts and other large openings; small cracks or wood splitting may be observed at bolted connections.
A16: 3 | B16: Extensive Damage | C16: N/A | D16: Large diagonal cracks across shear wall panels; large slack in diagonal rod braces and/or broken braces; permanent lateral movement of floors and roof; cracks in foundations; splitting of wood sill plates and/or slippage of structure over foundations; partial collapse of “soft-story” configurations; bolt slippage and wood splitting at bolted connections.
A17: 3 | B17: Complete Damage | C17: N/A | D17: Structure may have large permanent lateral displacement, may collapse or be in imminent danger of collapse due to failed shear walls, broken brace rods or failed framing connections; it may fall its foundations; large cracks in the foundations. Approximately 3% of the total area of W2 buildings with Complete damage is expected to be collapsed.
A18: 4 | B18: Utility Loss Severity by Damage Category | C18: Each cell must have a value greater than equal to 0 and smaller or equal to 1. | D18: Threshold used to Identify if the census tract is a low, medium or high damage tract based on the total number of destroyed and damaged buildings per tract
A19: 4 | B19: Low Severity | C19: N/A | D19: 0 - 10% buildings destroyed or 0-15% of buildings with extreme damage.
A20: 4 | B20: Medium Severity | C20: N/A | D20: 11 - 34% buildings destroyed or 16-34% of buildings with extreme damage.
A21: 4 | B21: High Severity | C21: N/A | D21: More than 35% of buildings destroyed or more than 35% of buildings with extreme damage.
A22: 4 | B22: Fully Usable | C22: N/A | D22: Building usability is the function of severity of observed damage to structural and non-structural elements of buildings. Fully usable buildings have the highest usability.
A23: 4 | B23: Partially Usable | C23: N/A | D23: Building usability is the function of severity of observed damage to structural and non-structural elements of buildings. Partially usable buildings have partial usability.
... A26: 5 | B26: SVI | C26: N/A | D26: Social Vulnerability Index - The CDC’s SVI is an index that ranks a tract's social vulnerability. SVI is a percentile ranking. Score ranges from 0 (lowest vulnerability) to 1 (highest vulnerability).

Sheet Overview
A1: Estimated Number of People Seeking Shelter
A2: =_xludf.CONCAT(ROUND(B12,0)," to ", ROUND(B13,0)) -> #NAME?
A4: Summary
A5: ="The storm surge event affected " & B10 & " census tracts, with an estimated total impacted population of " & TEXT(B11,"#,##0") & ". Based on our shelter demand model, the number of people expected to seek shelter ranges from approximately " & TEXT(B12,"0.0") & " (low estimate) to " & TEXT(B13,"0.0") & " (high estimate)." -> The storm surge event affected 2971 census tracts, with an estimated total impacted population of 13,024,672. Based on our shelter demand model, the number of people expected to seek shelter ranges from approximately 48.6 (low estimate) to 204.1 (high estimate).
A8: At a Glance
A9: Average Storm Surge Intensity | B9: =AVERAGE(final_output!B:B) -> 0.028327163
A10: Number of Tracts Impacted | B10: =COUNT(final_output!A:A) -> 2971
A11: Total Population Impacted | B11: =SUM(final_output!C:C) -> 13024672
A12: Total Shelter-Seeking Population - Low | B12: =SUM(final_output!H:H) -> 48.593793
A13: Total Shelter-Seeking Population - High | B13: =SUM(final_output!I:I) -> 204.08529
A15: Building Damage
A16: Damage Category | B16: Average | C16: Total | D16: % Total
A17: Slight | B17: =AVERAGE(final_output!J:J) -> 10.227483 | C17: =SUM(final_output!J:J) -> 30385.851 | D17: =C17/C21 -> 0.7622988
A18: Moderate | B18: =AVERAGE(final_output!K:K) -> 2.781241 | C18: =SUM(final_output!K:K) -> 8263.067 | D18: =C18/C21 -> 0.207298
A19: Extensive | B19: =AVERAGE(final_output!L:L) -> 0.35400377 | C19: =SUM(final_output!L:L) -> 1051.7452 | D19: =C19/C21 -> 0.026385441
A20: Complete | B20: =AVERAGE(final_output!M:M) -> 0.05390489 | C20: =SUM(final_output!M:M) -> 160.15143 | D20: =C20/C21 -> 0.004017766
A21: Total | B21: =AVERAGE(final_output!J:M) -> 3.3541581 | C21: =SUM(C17:C20) -> 39860.815

Sheet final_output
A1: GEOID | B1: max_intensity | C1: population | D1: Total_Num_Building | E1: risk_level | F1: BHI_factor_low | G1: BHI_factor_high | H1: shelter_seeking_low | I1: shelter_seeking_high | J1: Total_Num_Building_Slight | K1: Total_Num_Building_Moderate | L1: Total_Num_Building_Extensive | M1: Total_Num_Building_Complete | N1: SVI_Value | O1: SVI_Value_Mapped
A2: 6055201102 | B2: 0.6 | C2: 1811 | D2: 1482 | E2: low | F2: 8.0195137e-05 | G2: 0.0054549883 | H2: 0.0036308348 | I2: 0.24697459 | J2: 180.95017 | K2: 6.7682407 | L2: 0.3411391 | M2: 0.002474681 | N2: 0.5508 | O2: 0.025
A3: 6055200804 | B3: 0.58 | C3: 5535 | D3: 1036 | E3: low | F3: 0.017611402 | G3: 0.05757351 | H3: 2.4369777 | I3: 7.9667344 | J3: 451.35993 | K3: 403.33826 | L3: 46.768024 | M3: 4.2051322 | N3: 0.672 | O3: 0.025
A4: 6055200705 | B4: 0.58 | C4: 2845 | D4: 783 | E4: low | F4: 0.03084608 | G4: 0.071323564 | H4: 0 | I4: 0 | J4: 339.85655 | K4: 285.24734 | L4: 42.731014 | M4: 11.664694 | N4: 0.431 | O4: 0
A5: 6055200802 | B5: 0.58 | C5: 5887 | D5: 1322 | E5: low | F5: 0.0042670174 | G5: 0.032508343 | H5: 0.62799829 | I5: 4.7844153 | J5: 661.32124 | K5: 206.96142 | L5: 12.178839 | M5: 1.9718331 | N5: 0.7401 | O5: 0.025
A6: 6055200803 | B6: 0.58 | C6: 2149 | D6: 750 | E6: low | F6: 0.023976657 | G6: 0.066007078 | H6: 0 | I6: 0 | J6: 322.77932 | K6: 290.1458 | L6: 38.040681 | M6: 6.0678413 | N6: 0.4772 | O6: 0
A7: 6055200703 | B7: 0.58 | C7: 3078 | D7: 1182 | E7: low | F7: 0.012433338 | G7: 0.054257784 | H7: 0 | I7: 0 | J7: 551.07677 | K7: 412.60902 | L7: 36.69334 | M7: 1.9989533 | N7: 0.1565 | O7: 0
A8: 6055200201 | B8: 0.56 | C8: 3259 | D8: 1149 | E8: low | F8: 0.024742171 | G8: 0.061995149 | H8: 2.0158684 | I8: 5.0510547 | J8: 495.19717 | K8: 426.08801 | L8: 63.416952 | M8: 12.204563 | N8: 0.7605 | O8: 0.025
A9: 6055200203 | B9: 0.54 | C9: 2312 | D9: 661 | E9: low | F9: 0.011552773 | G9: 0.049497941 | H9: 1.3355005 | I9: 5.721962 | J9: 319.34047 | K9: 203.16425 | L9: 17.501117 | M9: 2.0602928 | N9: 0.8919 | O9: 0.05
A10: 6055200704 | B10: 0.54 | C10: 4493 | D10: 1284 | E10: low | F10: 0.01357282 | G10: 0.053491676 | H10: 1.524567 | I10: 6.0084525 | J10: 607.12938 | K10: 422.08679 | L10: 39.498107 | M10: 4.4819559 | N10: 0.7134 | O10: 0.025
A11: 6055200202 | B11: 0.54 | C11: 2479 | D11: 697 | E11: low | F11: 0.019390791 | G11: 0.053671846 | H11: 2.4034885 | I11: 6.6526254 | J11: 310.32374 | K11: 235.16347 | L11: 32.992116 | M11: 5.6362083 | N11: 0.8404 | O11: 0.05
A12: 6055201101 | B12: 0.54 | C12: 2077 | D12: 820 | E12: low | F12: 0.0087692489 | G12: 0.048817999 | H12: 0 | I12: 0 | J12: 401.78471 | K12: 248.52681 | L12: 17.254047 | M12: 0.91879922 | N12: 0.1857 | O12: 0
A13: 6055200501 | B13: 0.54 | C13: 5159 | D13: 1364 | E13: low | F13: 0.036991147 | G13: 0.070181786 | H13: 9.5418664 | I13: 18.103392 | J13: 606.29689 | K13: 385.24788 | L13: 91.773362 | M13: 31.991378 | N13: 0.8482 | O13: 0.05
... A249: 6013346102 | B249: 0.04 | C249: 5748 | D249: 2307 | E249: low | F249: 4.4068106e-11 | G249: 2.7965328e-06 | H249: 0 | I249: 0 | J249: 0.13240041 | K249: 1.6045136e-05 | L249: 1.4542395e-10 | M249: 1.0769506e-17 | N249: 0.0405 | O249: 0
A250: 6081984300 | B250: 0.04 | C250: 0 | D250: 143 | E250: low | F250: 0 | G250: 0 | J250: 0.62792067 | K250: 0.0013956686 | L250: 6.9432011e-07 | M250: 4.6961514e-11 | N250: -999
A251: 6013325000 | B251: 0.04 | C251: 5733 | D251: 1936 | E251: low | F251: 9.3192328e-09 | G251: 9.7697562e-05 | H251: 0 | I251: 0 | J251: 3.9090186 | K251: 0.0027845404 | L251: 2.033491e-06 | M251: 1.3609003e-10 | N251: 0.4432 | O251: 0
A252: 6013326000 | B252: 0.04 | C252: 3508 | D252: 1345 | E252: low | F252: 2.9746756e-09 | G252: 9.087306e-05 | H252: 0 | I252: 0 | J252: 2.4900845 | K252: 0.00061612682 | L252: 2.6135418e-07 | M252: 1.7610814e-11 | N252: 0.2601 | O252: 0
A253: 6013314106 | B253: 0.04 | C253: 3744 | D253: 1061 | E253: low | F253: 1.6048572e-09 | G253: 4.2655952e-05 | H253: 3.0042927e-07 | I253: 0.0079851943 | J253: 0.93755865 | K253: 0.0002713215 | L253: 2.505349e-09 | M253: 1.3526428e-16 | N253: 0.9165 | O253: 0.05
A254: 6013314105 | B254: 0.04 | C254: 4540 | D254: 937 | E254: low | F254: 1.5225701e-09 | G254: 4.0486979e-05 | H254: 3.4562341e-07 | I254: 0.0091905441 | J254: 0.82638829 | K254: 0.00023904246 | L254: 2.2071722e-09 | M254: 1.1930788e-16 | N254: 0.8381 | O254: 0.05
A255: 6081604104 | B255: 0.04 | C255: 3267 | D255: 652 | E255: low | F255: 3.2186636e-11 | G255: 2.7760637e-06 | H255: 2.6288435e-09 | I255: 0.000226735 | J255: 0.041043371 | K255: 3.6586798e-06 | L255: 5.2819643e-11 | M255: 2.7416514e-17 | N255: 0.6753 | O255: 0.025
A256: 6081604900 | B256: 0.04 | C256: 3387 | D256: 1026 | E256: low | F256: 3.7342554e-12 | G256: 1.7590013e-06 | H256: 3.1619807e-10 | I256: 0.00014894343 | J256: 0.037218578 | K256: 6.0762505e-07 | L256: 4.1880249e-12 | M256: 2.0167045e-18 | N256: 0.5025 | O256: 0.025
A257: 6081604400 | B257: 0.04 | C257: 5287 | D257: 949 | E257: low | F257: 2.0215149e-08 | G257: 0.00010580565 | H257: 2.6719373e-06 | I257: 0.013984862 | J257: 2.4023824 | K257: 0.0034357355 | L257: 2.3805933e-06 | M257: 1.5957079e-10 | N257: 0.6696 | O257: 0.025
A258: 6067009800 | B258: 0.04 | C258: 2183 | D258: 1128 | E258: low | F258: 1.4252366e-09 | G258: 3.7449462e-05 | H258: 7.7782285e-08 | I258: 0.0020438044 | J258: 1.5390739 | K258: 0.00045053718 | L258: 4.1819062e-09 | M258: 2.4718219e-16 | N258: 0.6828 | O258: 0.025
A259: 6013338102 | B259: 0.04 | C259: 3498 | D259: 1195 | E259: low | F259: 3.4458393e-12 | G259: 1.8188834e-06 | H259: 0 | I259: 0 | J259: 0.043800477 | K259: 6.3813433e-07 | L259: 4.1914377e-12 | M259: 2.0167061e-18 | N259: 0.1878 | O259: 0
A260: 6013338201 | B260: 0.04 | C260: 3814 | D260: 1438 | E260: low | F260: 1.6421049e-11 | G260: 2.2086412e-06 | H260: 0 | I260: 0 | J260: 0.071636557 | K260: 4.0949223e-06 | L260: 5.5613395e-11 | M260: 2.8760984e-17 | N260: 0.2974 | O260: 0
A261: 6081607500 | B261: 0.04 | C261: 6613 | D261: 893 | E261: low | F261: 1.6648797e-11 | G261: 2.1865734e-06 | H261: 0 | I261: 0 | J261: 0.049816155 | K261: 2.9160245e-06 | L261: 4.4961065e-11 | M261: 2.8191111e-17 | N261: 0.3258 | O261: 0
A262: 6081607600 | B262: 0.04 | C262: 4269 | D262: 1156 | E262: low | F262: 1.9582338e-11 | G262: 2.3719496e-06 | H262: 2.089925e-09 | I262: 0.00025314632 | J262: 0.058209262 | K262: 3.694676e-06 | L262: 5.2823183e-11 | M262: 2.7416515e-17 | N262: 0.5701 | O262: 0.025
... A337: 6095252915 | B337: 0.04 | C337: 6318 | D337: 1560 | E337: low | F337: 2.4978532e-12 | G337: 1.6822848e-06 | H337: 0 | I337: 0 | J337: 0.053306712 | K337: 6.0867453e-07 | L337: 4.1880145e-12 | M337: 2.0167045e-18 | N337: 0.1547 | O337: 0
A338: 6095253000 | B338: 0.04 | C338: 6640 | D338: 145 | E338: low | F338: 1.1871298e-08 | G338: 6.9527025e-05 | J338: 0.40546529 | K338: 0.0005223227 | L338: 2.5988808e-07 | M338: 1.7610421e-11 | N338: -999
A339: 6095253105 | B339: 0.04 | C339: 6489 | D339: 1286 | E339: low | F339: 7.6371521e-10 | G339: 2.1341325e-05 | H339: 1.238937e-07 | I339: 0.0034620965 | J339: 0.59249746 | K339: 0.000163085 | L339: 1.546946e-09 | M339: 1.2897438e-16 | N339: 0.6662 | O339: 0.025
A340: 6095253106 | B340: 0.04 | C340: 3427 | D340: 864 | E340: low | F340: 8.3419901e-09 | G340: 9.451595e-05 | H340: 7.147e-07 | I340: 0.008097654 | J340: 1.6707027 | K340: 0.0010867542 | L340: 1.1428211e-06 | M340: 9.6593539e-11 | N340: 0.5082 | O340: 0.025
A341: 6095253107 | B341: 0.04 | C341: 5999 | D341: 1599 | E341: low | F341: 3.8972845e-07 | G341: 0.00038678359 | H341: 5.8449525e-05 | I341: 0.058007869 | J341: 13.348979 | K341: 0.10137289 | L341: 7.0543005e-05 | M341: 9.9577757e-10 | N341: 0.641 | O341: 0.025
A342: 6095253201 | B342: 0.04 | C342: 4821 | D342: 1888 | E342: low | F342: 1.3856689e-07 | G342: 0.00019560914 | H342: 0 | I342: 0 | J342: 7.4764708 | K342: 0.03983504 | L342: 2.721407e-05 | M342: 3.3554629e-10 | N342: 0.1472 | O342: 0
A343: 6095253203 | B343: 0.04 | C343: 4179 | D343: 1350 | E343: low | F343: 6.8616016e-08 | G343: 0.00014145363 | H343: 0 | I343: 0 | J343: 4.0336145 | K343: 0.014676206 | L343: 1.0323909e-05 | M343: 2.2267145e-10 | N343: 0.4727 | O343: 0
A344: 6095253205 | B344: 0.04 | C344: 3091 | D344: 841 | E344: low | F344: 1.0598742e-10 | G344: 4.5181949e-06 | H344: 8.1901782e-09 | I344: 0.00034914351 | J344: 0.080376906 | K344: 1.4501023e-05 | L344: 1.3198495e-10 | M344: 8.855166e-18 | N344: 0.6664 | O344: 0.025
A345: 6095253206 | B345: 0.04 | C345: 3688 | D345: 1261 | E345: low | F345: 2.2606788e-12 | G345: 1.7174492e-06 | H345: 0 | I345: 0 | J345: 0.044732528 | K345: 4.5282098e-07 | L345: 2.7967232e-12 | M345: 1.3444718e-18 | N345: 0.0398 | O345: 0
A346: 6095253207 | B346: 0.04 | C346: 2332 | D346: 834 | E346: low | F346: 1.7226551e-07 | G346: 0.00023224646 | H346: 0 | I346: 0 | J346: 3.9247933 | K346: 0.021909542 | L346: 1.4790483e-05 | M346: 1.9607161e-10 | N346: 0.2733 | O346: 0
A347: 6095253208 | B347: 0.04 | C347: 5173 | D347: 1224 | E347: low | F347: 1.6771149e-07 | G347: 0.00022674135 | H347: 2.1689289e-05 | I347: 0.029323326 | J347: 5.7458235 | K347: 0.03198489 | L347: 2.1590433e-05 | M347: 2.8476006e-10 | N347: 0.7255 | O347: 0.025
A348: 6095253300 | B348: 0.04 | C348: 2527 | D348: 2793 | E348: low | F348: 2.0488258e-10 | G348: 6.4903444e-06 | H348: 0 | I348: 0 | J348: 0.63708381 | K348: 0.00015468255 | L348: 1.4174303e-09 | M348: 8.5408952e-17 | N348: 0.4966 | O348: 0
A349: 6095253501 | B349: 0.04 | C349: 6327 | D349: 3200 | E349: low | F349: 3.3683945e-11 | G349: 4.9409631e-06 | H349: 0 | I349: 0 | J349: 0.38842584 | K349: 2.0365122e-05 | L349: 1.2724861e-10 | M349: 6.1173468e-17 | N349: 0.4259 | O349: 0
...

Sheet process flow

Sheet building usability & utility lo
A1: Storm Surge Shelter Demand Model – Input Configuration
A2: Welcome! This interface is designed to help the user configure inputs for the Storm Surge Shelter Demand Model. Instructions: - Step 1: Required inputs from NHC forecasts. - Steps 2, 3, 4, 5: Inputs are filled with default values. Modification of these inputs is optional and at the user's discretion (refer to Data Dictionary tab). - Step 5: A Python code snippet will be automatically generated. Copy directly into Google Colab. - Step 6: Paste code snipper directly from Google Colab.
A3: Select the variable names to see their definition and any associated data validation rules
A4: Step 1: Required inputs from NHC forecasts
A6: Storm ID
A7: Storm Name
A8: # of Latest Advisory
A9: Year | C9: 2026
A11: Step : Criteria for damage levels (optional)
A12: Damage Type | C12: % Destroyed | D12: % Major Damage
A13: High | C13: 0.35 | D13: 0.35
A14: Medium | C14: 11 - 34 | D14: 16 - 34
A15: Low | C15: 0 - 10 | D15: 0 - 15
A16: Step 3: Building Usability Thresholds (optional)
A17: Damage Type | C17: % Fully Usable | D17: % Partially Usable | E17: % Non-Usable
A18: Slight | C18: 1 | D18: 0 | E18: 0
A19: Moderate | C19: 0.87 | D19: 0.13 | E19: 0
A20: Extensive | C20: 0.25 | D20: 0.5 | E20: 0.25
A21: Complete | C21: 0 | D21: 0.02 | E21: 0.98
A22: Step 4: Utility Loss Severity by Damage Category (optional)
A23: % Non-Habitable | B23: Fully Usable Buildings | D23: Partially Usable Buildings
A24: Severity | B24: Low | C24: High | D24: Low | E24: High
A25: Low | B25: 0 | C25: 0.05 | D25: 0.05 | E25: 0.1
A26: Medium | B26: 0 | C26: 0.1 | D26: 0.3 | E26: 0.5
A27: High | B27: 0.1 | C27: 0.3 | D27: 0.6 | E27: 0.8
A28: Step 5: SVI Mapping Threshold (optional)
A29: SVI Range | D29: % Non-Habitable Residents Seeking Shelter
A30: 0.0-0.4 | D30: 0
A31: 0.4-0.8 | D31: 0.025
A32: 0.8-1.0 | D32: 0.05
A33: Step 6: Copy the output from the cell below
A34: ="params = {" & CHAR(10) & """event_id"": """ & C6 & """," & CHAR(10) & """BLDNG_USABILITY"": {" & CHAR(10) & """Slight"":{""FU"":" & TEXT(C18,"0.00") & ",""PU"":" & TEXT(D18,"0.00") & ",""NU"":" & TEXT(E18,"0.00") & "}," & CHAR(10) & """Moderate"":{""FU"":" & TEXT(C19,"0.00") & ",""PU"":" & TEXT(D19,"0.00") & ",""NU"":" & TEXT(E19,"0.00") & "}," & CHAR(10) & """Extensive"":{""FU"":" & TEXT(C20,"0.00") & ",""PU"":" & TEXT(D20,"0.00") & ",""NU"":" & TEXT(E20,"0.00") & "}," & CHAR(10) & """Complete"":{""FU"":" & TEXT(C21,"0.00") & ",""PU"":" & TEXT(D21,"0.00") & ",""NU"":" & TEXT(E21,"0.00") & "}" & CHAR(10) & "}," & CHAR(10) & """UL_SEVERITY"": {" & CHAR(10) & """low"": {""FU"": [" & TEXT(B25,"0.00") & "," & TEXT(C25,"0.00") & "], ""PU"": [" & TEXT(D25,"0.00") & "," & TEXT(E25,"0.00") & "]}," & CHAR(10) & """medium"": {""FU"": [" & TEXT(B26,"0.00") & "," & TEXT(C26,"0.00") & "], ""PU"": [" & TEXT(D26,"0.00") & "," & TEXT(E26,"0.00") & "]}," & CHAR(10) & """high"": {""FU"": [" & TEXT(B27,"0.00") & "," & TEXT(C27,"0.00") & "], ""PU"": [" & TEXT(D27,"0.00") & "," & TEXT(E27,"0.00") & "]}" & CHAR(10) & "}," & CHAR(10) & """SVI_THRESHOLD"": [ " & TEXT(D30,"0.000") & ", " & TEXT(D31,"0.000") & ", " & TEXT(D32,"0.000") & " ]" & CHAR(10) & "}" -> params = { "event_id": "", "BLDNG_USABILITY": { "Slight":{"FU":1.00,"PU":0.00,"NU":0.00}, "Moderate":{"FU":0.87,"PU":0.13,"NU":0.00}, "Extensive":{"FU":0.25,"PU":0.50,"NU":0.25}, "Complete":{"FU":0.00,"PU":0.02,"NU":0.98} }, "UL_SEVERITY": { "low": {"FU": [0.00,0.05], "PU": [0.05,0.10]}, "medium": {"FU": [0.00,0.10], "PU": [0.30,0.50]}, "high": {"FU": [0.10,0.30], "PU": [0.60,0.80]} }, "SVI_THRESHOLD": [ 0.000, 0.025, 0.050 ] }
A35: Step 7: Click on the Paste button to transfer the outputs here
A36: params = { "event_id": "ci3144585", "intensity_metric": "min", "BLDNG_USABILITY": { "Slight":{"FU":1.00,"PU":0.00,"NU":0.00}, "Moderate":{"FU":0.87,"PU":0.13,"NU":0.00}, "Extensive":{"FU":0.25,"PU":0.50,"NU":0.25}, "Complete":{"FU":0.00,"PU":0.02,"NU":0.98} }, "UL_SEVERITY": { "low": {"FU": [0.00,0.05], "PU": [0.05,0.10]}, "medium": {"FU": [0.00,0.10], "PU": [0.30,0.50]}, "high": {"FU": [0.10,0.30], "PU": [0.60,0.80]} }, "SVI_THRESHOLD": [ 0.000, 0.025, 0.050 ] }
